Workbook

Sheet Dashboard
A1: CAR SALES ANALYSIS DASHBOARD
A3: Insights from 157 vehicle models across 30 manufacturers | Source: Car_sales.csv
B5: TOTAL SALES | E5: AVERAGE PRICE | H5: AVERAGE HORSEPOWER | K5: TOTAL MODELS | N5: TOTAL MANUFACTURERS
B6: =Analysis!$R$3 -> 8320.698 | E6: =Analysis!$R$4 -> 27.339707 | H6: =Analysis!$R$5 -> 185.94268 | K6: =Analysis!$R$6 -> 157 | N6: =Analysis!$R$7 -> 30

Sheet Raw_Data
A1: Manufacturer | B1: Model | C1: Sales_in_thousands | D1: __year_resale_value | E1: Vehicle_type | F1: Price_in_thousands | G1: Engine_size | H1: Horsepower | I1: Wheelbase | J1: Width | K1: Length | L1: Curb_weight | M1: Fuel_capacity | N1: Fuel_efficiency | O1: Latest_Launch | P1: Power_perf_factor
A2: Acura | B2: Integra | C2: 16.919 | D2: 16.36 | E2: Passenger | F2: 21.5 | G2: 1.8 | H2: 140 | I2: 101.2 | J2: 67.3 | K2: 172.4 | L2: 2.639 | M2: 13.2 | N2: 28 | O2: 2/2/2012 | P2: 58.28015
A3: Acura | B3: TL | C3: 39.384 | D3: 19.875 | E3: Passenger | F3: 28.4 | G3: 3.2 | H3: 225 | I3: 108.1 | J3: 70.3 | K3: 192.9 | L3: 3.517 | M3: 17.2 | N3: 25 | O3: 6/3/2011 | P3: 91.370778
A4: Acura | B4: CL | C4: 14.114 | D4: 18.225 | E4: Passenger | G4: 3.2 | H4: 225 | I4: 106.9 | J4: 70.6 | K4: 192 | L4: 3.47 | M4: 17.2 | N4: 26 | O4: 1/4/2012
A5: Acura | B5: RL | C5: 8.588 | D5: 29.725 | E5: Passenger | F5: 42 | G5: 3.5 | H5: 210 | I5: 114.6 | J5: 71.4 | K5: 196.6 | L5: 3.85 | M5: 18 | N5: 22 | O5: 3/10/2011 | P5: 91.389779
A6: Audi | B6: A4 | C6: 20.397 | D6: 22.255 | E6: Passenger | F6: 23.99 | G6: 1.8 | H6: 150 | I6: 102.6 | J6: 68.2 | K6: 178 | L6: 2.998 | M6: 16.4 | N6: 27 | O6: 10/8/2011 | P6: 62.777639
A7: Audi | B7: A6 | C7: 18.78 | D7: 23.555 | E7: Passenger | F7: 33.95 | G7: 2.8 | H7: 200 | I7: 108.7 | J7: 76.1 | K7: 192 | L7: 3.561 | M7: 18.5 | N7: 22 | O7: 8/9/2011 | P7: 84.565105
A8: Audi | B8: A8 | C8: 1.38 | D8: 39 | E8: Passenger | F8: 62 | G8: 4.2 | H8: 310 | I8: 113 | J8: 74 | K8: 198.2 | L8: 3.902 | M8: 23.7 | N8: 21 | O8: 2/27/2012 | P8: 134.65686
A9: BMW | B9: 323i | C9: 19.747 | E9: Passenger | F9: 26.99 | G9: 2.5 | H9: 170 | I9: 107.3 | J9: 68.4 | K9: 176 | L9: 3.179 | M9: 16.6 | N9: 26 | O9: 6/28/2011 | P9: 71.191207
A10: BMW | B10: 328i | C10: 9.231 | D10: 28.675 | E10: Passenger | F10: 33.4 | G10: 2.8 | H10: 193 | I10: 107.3 | J10: 68.5 | K10: 176 | L10: 3.197 | M10: 16.6 | N10: 24 | O10: 1/29/2012 | P10: 81.877069
A11: BMW | B11: 528i | C11: 17.527 | D11: 36.125 | E11: Passenger | F11: 38.9 | G11: 2.8 | H11: 193 | I11: 111.4 | J11: 70.9 | K11: 188 | L11: 3.472 | M11: 18.5 | N11: 25 | O11: 4/4/2011 | P11: 83.998724
A12: Buick | B12: Century | C12: 91.561 | D12: 12.475 | E12: Passenger | F12: 21.975 | G12: 3.1 | H12: 175 | I12: 109 | J12: 72.7 | K12: 194.6 | L12: 3.368 | M12: 17.5 | N12: 25 | O12: 11/2/2011 | P12: 71.181451
A13: Buick | B13: Regal | C13: 39.35 | D13: 13.74 | E13: Passenger | F13: 25.3 | G13: 3.8 | H13: 240 | I13: 109 | J13: 72.7 | K13: 196.2 | L13: 3.543 | M13: 17.5 | N13: 23 | O13: 9/3/2011 | P13: 95.636703
A14: Buick | B14: Park Avenue | C14: 27.851 | D14: 20.19 | E14: Passenger | F14: 31.965 | G14: 3.8 | H14: 205 | I14: 113.8 | J14: 74.7 | K14: 206.8 | L14: 3.778 | M14: 18.5 | N14: 24 | O14: 3/23/2012 | P14: 85.828408
A15: Buick | B15: LeSabre | C15: 83.257 | D15: 13.36 | E15: Passenger | F15: 27.885 | G15: 3.8 | H15: 205 | I15: 112.2 | J15: 73.5 | K15: 200 | L15: 3.591 | M15: 17.5 | N15: 25 | O15: 7/23/2011 | P15: 84.254526
A16: Cadillac | B16: DeVille | C16: 63.729 | D16: 22.525 | E16: Passenger | F16: 39.895 | G16: 4.6 | H16: 275 | I16: 115.3 | J16: 74.5 | K16: 207.2 | L16: 3.978 | M16: 18.5 | N16: 22 | O16: 2/23/2012 | P16: 113.8546
A17: Cadillac | B17: Seville | C17: 15.943 | D17: 27.1 | E17: Passenger | F17: 44.475 | G17: 4.6 | H17: 275 | I17: 112.2 | J17: 75 | K17: 201 | M17: 18.5 | N17: 22 | O17: 4/29/2011 | P17: 115.62136
A18: Cadillac | B18: Eldorado | C18: 6.536 | D18: 25.725 | E18: Passenger | F18: 39.665 | G18: 4.6 | H18: 275 | I18: 108 | J18: 75.5 | K18: 200.6 | L18: 3.843 | M18: 19 | N18: 22 | O18: 11/27/2011 | P18: 113.76587
A19: Cadillac | B19: Catera | C19: 11.185 | D19: 18.225 | E19: Passenger | F19: 31.01 | G19: 3 | H19: 200 | I19: 107.4 | J19: 70.3 | K19: 194.8 | L19: 3.77 | M19: 18 | N19: 22 | O19: 9/28/2011 | P19: 83.483094
A20: Cadillac | B20: Escalade | C20: 14.785 | E20: Car | F20: 46.225 | G20: 5.7 | H20: 255 | I20: 117.5 | J20: 77 | K20: 201.2 | L20: 5.572 | M20: 30 | N20: 15 | O20: 4/17/2012 | P20: 109.50912
A21: Chevrolet | B21: Cavalier | C21: 145.519 | D21: 9.25 | E21: Passenger | F21: 13.26 | G21: 2.2 | H21: 115 | I21: 104.1 | J21: 67.9 | K21: 180.9 | L21: 2.676 | M21: 14.3 | N21: 27 | O21: 8/17/2011 | P21: 46.363347
A22: Chevrolet | B22: Malibu | C22: 135.126 | D22: 11.225 | E22: Passenger | F22: 16.535 | G22: 3.1 | H22: 170 | I22: 107 | J22: 69.4 | K22: 190.4 | L22: 3.051 | M22: 15 | N22: 25 | O22: 3/19/2012 | P22: 67.314462
A23: Chevrolet | B23: Lumina | C23: 24.629 | D23: 10.31 | E23: Passenger | F23: 18.89 | G23: 3.1 | H23: 175 | I23: 107.5 | J23: 72.5 | K23: 200.9 | L23: 3.33 | M23: 16.6 | N23: 25 | O23: 5/24/2011 | P23: 69.991396
A24: Chevrolet | B24: Monte Carlo | C24: 42.593 | D24: 11.525 | E24: Passenger | F24: 19.39 | G24: 3.4 | H24: 180 | I24: 110.5 | J24: 72.7 | K24: 197.9 | L24: 3.34 | M24: 17 | N24: 27 | O24: 12/22/2011 | P24: 72.030917
A25: Chevrolet | B25: Camaro | C25: 26.402 | D25: 13.025 | E25: Passenger | F25: 24.34 | G25: 3.8 | H25: 200 | I25: 101.1 | J25: 74.1 | K25: 193.2 | L25: 3.5 | M25: 16.8 | N25: 25 | O25: 10/23/2011 | P25: 81.118543
A26: Chevrolet | B26: Corvette | C26: 17.947 | D26: 36.225 | E26: Passenger | F26: 45.705 | G26: 5.7 | H26: 345 | I26: 104.5 | J26: 73.6 | K26: 179.7 | L26: 3.21 | M26: 19.1 | N26: 22 | O26: 5/12/2012 | P26: 141.14115
A27: Chevrolet | B27: Prizm | C27: 32.299 | D27: 9.125 | E27: Passenger | F27: 13.96 | G27: 1.8 | H27: 120 | I27: 97.1 | J27: 66.7 | K27: 174.3 | L27: 2.398 | M27: 13.2 | N27: 33 | O27: 9/11/2011 | P27: 48.297636
A28: Chevrolet | B28: Metro | C28: 21.855 | D28: 5.16 | E28: Passenger | F28: 9.235 | G28: 1 | H28: 55 | I28: 93.1 | J28: 62.6 | K28: 149.4 | L28: 1.895 | M28: 10.3 | N28: 45 | O28: 4/13/2012 | P28: 23.276272
A29: Chevrolet | B29: Impala | C29: 107.995 | E29: Passenger | F29: 18.89 | G29: 3.4 | H29: 180 | I29: 110.5 | J29: 73 | K29: 200 | L29: 3.389 | M29: 17 | N29: 27 | O29: 6/18/2011 | P29: 71.838039
A30: Chrysler | B30: Sebring Coupe | C30: 7.854 | D30: 12.36 | E30: Passenger | F30: 19.84 | G30: 2.5 | H30: 163 | I30: 103.7 | J30: 69.7 | K30: 190.9 | L30: 2.967 | M30: 15.9 | N30: 24 | O30: 1/16/2012 | P30: 65.957184
A31: Chrysler | B31: Sebring Conv. | C31: 32.775 | D31: 14.18 | E31: Passenger | F31: 24.495 | G31: 2.5 | H31: 168 | I31: 106 | J31: 69.2 | K31: 193 | L31: 3.332 | M31: 16 | N31: 24 | O31: 11/17/2011 | P31: 69.521355
A32: Chrysler | B32: Concorde | C32: 31.148 | D32: 13.725 | E32: Passenger | F32: 22.245 | G32: 2.7 | H32: 200 | I32: 113 | J32: 74.4 | K32: 209.1 | L32: 3.452 | M32: 17 | N32: 26 | O32: 6/6/2012 | P32: 80.023782
A33: Chrysler | B33: Cirrus | C33: 32.306 | D33: 12.64 | E33: Passenger | F33: 16.48 | G33: 2 | H33: 132 | I33: 108 | J33: 71 | K33: 186 | L33: 2.911 | M33: 16 | N33: 27 | O33: 10/6/2011 | P33: 53.5662
A34: Chrysler | B34: LHS | C34: 13.462 | D34: 17.325 | E34: Passenger | F34: 28.34 | G34: 3.5 | H34: 253 | I34: 113 | J34: 74.4 | K34: 207.7 | L34: 3.564 | M34: 17 | N34: 23 | O34: 5/8/2012 | P34: 101.32928
A35: Chrysler | B35: Town & Country | C35: 53.48 | D35: 19.54 | E35: Car | O35: 7/13/2011
A36: Chrysler | B36: 300M | C36: 30.696 | E36: Passenger | F36: 29.185 | G36: 3.5 | H36: 253 | I36: 113 | J36: 74.4 | K36: 197.8 | L36: 3.567 | M36: 17 | N36: 23 | O36: 2/10/2012 | P36: 101.65524
A37: Dodge | B37: Neon | C37: 76.034 | D37: 7.75 | E37: Passenger | F37: 12.64 | G37: 2 | H37: 132 | I37: 105 | J37: 74.4 | K37: 174.4 | L37: 2.567 | M37: 12.5 | N37: 29 | O37: 12/12/2011 | P37: 52.084899
A38: Dodge | B38: Avenger | C38: 4.734 | D38: 12.545 | E38: Passenger | F38: 19.045 | G38: 2.5 | H38: 163 | I38: 103.7 | J38: 69.1 | K38: 190.2 | L38: 2.879 | M38: 15.9 | N38: 24 | O38: 7/1/2012 | P38: 65.650508
A39: Dodge | B39: Stratus | C39: 71.186 | D39: 10.185 | E39: Passenger | F39: 20.23 | G39: 2.5 | H39: 168 | I39: 108 | J39: 71 | K39: 186 | L39: 3.058 | M39: 16 | N39: 24 | O39: 10/31/2011 | P39: 67.876108
A40: Dodge | B40: Intrepid | C40: 88.028 | D40: 12.275 | E40: Passenger | F40: 22.505 | G40: 2.7 | H40: 202 | I40: 113 | J40: 74.7 | K40: 203.7 | L40: 3.489 | M40: 17 | O40: 6/2/2012 | P40: 80.83147
...

Sheet Cleaned_Data
A1: Manufacturer | B1: Model | C1: Sales_in_thousands | D1: __year_resale_value | E1: Vehicle_type | F1: Price_in_thousands | G1: Engine_size | H1: Horsepower | I1: Wheelbase | J1: Width | K1: Length | L1: Curb_weight | M1: Fuel_capacity | N1: Fuel_efficiency | O1: Latest_Launch | P1: Power_perf_factor
A2: Acura | B2: Integra | C2: 16.919 | D2: 16.36 | E2: Passenger | F2: 21.5 | G2: 1.8 | H2: 140 | I2: 101.2 | J2: 67.3 | K2: 172.4 | L2: 2.639 | M2: 13.2 | N2: 28 | O2: 40941 | P2: 58.28015
A3: Acura | B3: TL | C3: 39.384 | D3: 19.875 | E3: Passenger | F3: 28.4 | G3: 3.2 | H3: 225 | I3: 108.1 | J3: 70.3 | K3: 192.9 | L3: 3.517 | M3: 17.2 | N3: 25 | O3: 40697 | P3: 91.370778
A4: Acura | B4: CL | C4: 14.114 | D4: 18.225 | E4: Passenger | F4: 22.695 | G4: 3.2 | H4: 225 | I4: 106.9 | J4: 70.6 | K4: 192 | L4: 3.47 | M4: 17.2 | N4: 26 | O4: 40912 | P4: 71.191
A5: Acura | B5: RL | C5: 8.588 | D5: 29.725 | E5: Passenger | F5: 42 | G5: 3.5 | H5: 210 | I5: 114.6 | J5: 71.4 | K5: 196.6 | L5: 3.85 | M5: 18 | N5: 22 | O5: 40612 | P5: 91.389779
A6: Audi | B6: A4 | C6: 20.397 | D6: 22.255 | E6: Passenger | F6: 23.99 | G6: 1.8 | H6: 150 | I6: 102.6 | J6: 68.2 | K6: 178 | L6: 2.998 | M6: 16.4 | N6: 27 | O6: 40824 | P6: 62.777639
A7: Audi | B7: A6 | C7: 18.78 | D7: 23.555 | E7: Passenger | F7: 33.95 | G7: 2.8 | H7: 200 | I7: 108.7 | J7: 76.1 | K7: 192 | L7: 3.561 | M7: 18.5 | N7: 22 | O7: 40764 | P7: 84.565105
A8: Audi | B8: A8 | C8: 1.38 | D8: 39 | E8: Passenger | F8: 62 | G8: 4.2 | H8: 310 | I8: 113 | J8: 74 | K8: 198.2 | L8: 3.902 | M8: 23.7 | N8: 21 | O8: 40966 | P8: 134.65686
A9: BMW | B9: 323i | C9: 19.747 | E9: Passenger | F9: 26.99 | G9: 2.5 | H9: 170 | I9: 107.3 | J9: 68.4 | K9: 176 | L9: 3.179 | M9: 16.6 | N9: 26 | O9: 40722 | P9: 71.191207
A10: BMW | B10: 328i | C10: 9.231 | D10: 28.675 | E10: Passenger | F10: 33.4 | G10: 2.8 | H10: 193 | I10: 107.3 | J10: 68.5 | K10: 176 | L10: 3.197 | M10: 16.6 | N10: 24 | O10: 40937 | P10: 81.877069
A11: BMW | B11: 528i | C11: 17.527 | D11: 36.125 | E11: Passenger | F11: 38.9 | G11: 2.8 | H11: 193 | I11: 111.4 | J11: 70.9 | K11: 188 | L11: 3.472 | M11: 18.5 | N11: 25 | O11: 40637 | P11: 83.998724
A12: Buick | B12: Century | C12: 91.561 | D12: 12.475 | E12: Passenger | F12: 21.975 | G12: 3.1 | H12: 175 | I12: 109 | J12: 72.7 | K12: 194.6 | L12: 3.368 | M12: 17.5 | N12: 25 | O12: 40849 | P12: 71.181451
A13: Buick | B13: Regal | C13: 39.35 | D13: 13.74 | E13: Passenger | F13: 25.3 | G13: 3.8 | H13: 240 | I13: 109 | J13: 72.7 | K13: 196.2 | L13: 3.543 | M13: 17.5 | N13: 23 | O13: 40789 | P13: 95.636703
A14: Buick | B14: Park Avenue | C14: 27.851 | D14: 20.19 | E14: Passenger | F14: 31.965 | G14: 3.8 | H14: 205 | I14: 113.8 | J14: 74.7 | K14: 206.8 | L14: 3.778 | M14: 18.5 | N14: 24 | O14: 40991 | P14: 85.828408
A15: Buick | B15: LeSabre | C15: 83.257 | D15: 13.36 | E15: Passenger | F15: 27.885 | G15: 3.8 | H15: 205 | I15: 112.2 | J15: 73.5 | K15: 200 | L15: 3.591 | M15: 17.5 | N15: 25 | O15: 40747 | P15: 84.254526
A16: Cadillac | B16: DeVille | C16: 63.729 | D16: 22.525 | E16: Passenger | F16: 39.895 | G16: 4.6 | H16: 275 | I16: 115.3 | J16: 74.5 | K16: 207.2 | L16: 3.978 | M16: 18.5 | N16: 22 | O16: 40962 | P16: 113.8546
A17: Cadillac | B17: Seville | C17: 15.943 | D17: 27.1 | E17: Passenger | F17: 44.475 | G17: 4.6 | H17: 275 | I17: 112.2 | J17: 75 | K17: 201 | L17: 3.197 | M17: 18.5 | N17: 22 | O17: 40662 | P17: 115.62136
A18: Cadillac | B18: Eldorado | C18: 6.536 | D18: 25.725 | E18: Passenger | F18: 39.665 | G18: 4.6 | H18: 275 | I18: 108 | J18: 75.5 | K18: 200.6 | L18: 3.843 | M18: 19 | N18: 22 | O18: 40874 | P18: 113.76587
A19: Cadillac | B19: Catera | C19: 11.185 | D19: 18.225 | E19: Passenger | F19: 31.01 | G19: 3 | H19: 200 | I19: 107.4 | J19: 70.3 | K19: 194.8 | L19: 3.77 | M19: 18 | N19: 22 | O19: 40814 | P19: 83.483094
A20: Cadillac | B20: Escalade | C20: 14.785 | E20: Car | F20: 46.225 | G20: 5.7 | H20: 255 | I20: 117.5 | J20: 77 | K20: 201.2 | L20: 5.572 | M20: 30 | N20: 15 | O20: 41016 | P20: 109.50912
A21: Chevrolet | B21: Cavalier | C21: 145.519 | D21: 9.25 | E21: Passenger | F21: 13.26 | G21: 2.2 | H21: 115 | I21: 104.1 | J21: 67.9 | K21: 180.9 | L21: 2.676 | M21: 14.3 | N21: 27 | O21: 40772 | P21: 46.363347
A22: Chevrolet | B22: Malibu | C22: 135.126 | D22: 11.225 | E22: Passenger | F22: 16.535 | G22: 3.1 | H22: 170 | I22: 107 | J22: 69.4 | K22: 190.4 | L22: 3.051 | M22: 15 | N22: 25 | O22: 40987 | P22: 67.314462
A23: Chevrolet | B23: Lumina | C23: 24.629 | D23: 10.31 | E23: Passenger | F23: 18.89 | G23: 3.1 | H23: 175 | I23: 107.5 | J23: 72.5 | K23: 200.9 | L23: 3.33 | M23: 16.6 | N23: 25 | O23: 40687 | P23: 69.991396
A24: Chevrolet | B24: Monte Carlo | C24: 42.593 | D24: 11.525 | E24: Passenger | F24: 19.39 | G24: 3.4 | H24: 180 | I24: 110.5 | J24: 72.7 | K24: 197.9 | L24: 3.34 | M24: 17 | N24: 27 | O24: 40899 | P24: 72.030917
A25: Chevrolet | B25: Camaro | C25: 26.402 | D25: 13.025 | E25: Passenger | F25: 24.34 | G25: 3.8 | H25: 200 | I25: 101.1 | J25: 74.1 | K25: 193.2 | L25: 3.5 | M25: 16.8 | N25: 25 | O25: 40839 | P25: 81.118543
A26: Chevrolet | B26: Corvette | C26: 17.947 | D26: 36.225 | E26: Passenger | F26: 45.705 | G26: 5.7 | H26: 345 | I26: 104.5 | J26: 73.6 | K26: 179.7 | L26: 3.21 | M26: 19.1 | N26: 22 | O26: 41041 | P26: 141.14115
A27: Chevrolet | B27: Prizm | C27: 32.299 | D27: 9.125 | E27: Passenger | F27: 13.96 | G27: 1.8 | H27: 120 | I27: 97.1 | J27: 66.7 | K27: 174.3 | L27: 2.398 | M27: 13.2 | N27: 33 | O27: 40797 | P27: 48.297636
A28: Chevrolet | B28: Metro | C28: 21.855 | D28: 5.16 | E28: Passenger | F28: 9.235 | G28: 1 | H28: 55 | I28: 93.1 | J28: 62.6 | K28: 149.4 | L28: 1.895 | M28: 10.3 | N28: 45 | O28: 41012 | P28: 23.276272
A29: Chevrolet | B29: Impala | C29: 107.995 | E29: Passenger | F29: 18.89 | G29: 3.4 | H29: 180 | I29: 110.5 | J29: 73 | K29: 200 | L29: 3.389 | M29: 17 | N29: 27 | O29: 40712 | P29: 71.838039
A30: Chrysler | B30: Sebring Coupe | C30: 7.854 | D30: 12.36 | E30: Passenger | F30: 19.84 | G30: 2.5 | H30: 163 | I30: 103.7 | J30: 69.7 | K30: 190.9 | L30: 2.967 | M30: 15.9 | N30: 24 | O30: 40924 | P30: 65.957184
A31: Chrysler | B31: Sebring Conv. | C31: 32.775 | D31: 14.18 | E31: Passenger | F31: 24.495 | G31: 2.5 | H31: 168 | I31: 106 | J31: 69.2 | K31: 193 | L31: 3.332 | M31: 16 | N31: 24 | O31: 40864 | P31: 69.521355
A32: Chrysler | B32: Concorde | C32: 31.148 | D32: 13.725 | E32: Passenger | F32: 22.245 | G32: 2.7 | H32: 200 | I32: 113 | J32: 74.4 | K32: 209.1 | L32: 3.452 | M32: 17 | N32: 26 | O32: 41066 | P32: 80.023782
A33: Chrysler | B33: Cirrus | C33: 32.306 | D33: 12.64 | E33: Passenger | F33: 16.48 | G33: 2 | H33: 132 | I33: 108 | J33: 71 | K33: 186 | L33: 2.911 | M33: 16 | N33: 27 | O33: 40822 | P33: 53.5662
A34: Chrysler | B34: LHS | C34: 13.462 | D34: 17.325 | E34: Passenger | F34: 28.34 | G34: 3.5 | H34: 253 | I34: 113 | J34: 74.4 | K34: 207.7 | L34: 3.564 | M34: 17 | N34: 23 | O34: 41037 | P34: 101.32928
A35: Chrysler | B35: Town & Country | C35: 53.48 | D35: 19.54 | E35: Car | F35: 24.072 | G35: 3.3 | H35: 185 | I35: 112.2 | J35: 71.95 | K35: 191.6 | L35: 3.89 | M35: 20.7 | N35: 19 | O35: 40737 | P35: 76.153
A36: Chrysler | B36: 300M | C36: 30.696 | E36: Passenger | F36: 29.185 | G36: 3.5 | H36: 253 | I36: 113 | J36: 74.4 | K36: 197.8 | L36: 3.567 | M36: 17 | N36: 23 | O36: 40949 | P36: 101.65524
A37: Dodge | B37: Neon | C37: 76.034 | D37: 7.75 | E37: Passenger | F37: 12.64 | G37: 2 | H37: 132 | I37: 105 | J37: 74.4 | K37: 174.4 | L37: 2.567 | M37: 12.5 | N37: 29 | O37: 40889 | P37: 52.084899
A38: Dodge | B38: Avenger | C38: 4.734 | D38: 12.545 | E38: Passenger | F38: 19.045 | G38: 2.5 | H38: 163 | I38: 103.7 | J38: 69.1 | K38: 190.2 | L38: 2.879 | M38: 15.9 | N38: 24 | O38: 41091 | P38: 65.650508
A39: Dodge | B39: Stratus | C39: 71.186 | D39: 10.185 | E39: Passenger | F39: 20.23 | G39: 2.5 | H39: 168 | I39: 108 | J39: 71 | K39: 186 | L39: 3.058 | M39: 16 | N39: 24 | O39: 40847 | P39: 67.876108
A40: Dodge | B40: Intrepid | C40: 88.028 | D40: 12.275 | E40: Passenger | F40: 22.505 | G40: 2.7 | H40: 202 | I40: 113 | J40: 74.7 | K40: 203.7 | L40: 3.489 | M40: 17 | N40: 25 | O40: 41062 | P40: 80.83147
...

Sheet Analysis
A1: 1. Total Sales by Manufacturer | D1: 2. Average Price by Vehicle Type | G1: 3. Top 10 Best-Selling Car Models | K1: 4. Average Horsepower by Vehicle Type | N1: 5. Total Sales by Vehicle Type | Q1: KPI Support Calculations
A2: Manufacturer | B2: Total Sales ($000s) | D2: Vehicle Type | E2: Avg Price ($000s) | G2: Manufacturer | H2: Model | I2: Sales ($000s) | K2: Vehicle Type | L2: Avg Horsepower | N2: Vehicle Type | O2: Total Sales ($000s) | Q2: KPI | R2: Value
A3: Ford | B3: =SUMIFS(Cleaned_Data!$C$2:$C$158,Cleaned_Data!$A$2:$A$158,A3) -> 2022.635 | D3: Car | E3: =AVERAGEIFS(Cleaned_Data!$F$2:$F$158,Cleaned_Data!$E$2:$E$158,D3) -> 26.265146 | G3: Ford | H3: F-Series | I3: =SUMIFS(Cleaned_Data!$C$2:$C$158,Cleaned_Data!$A$2:$A$158,G3,Cleaned_Data!$B$2:$B$158,H3) -> 540.561 | K3: Car | L3: =AVERAGEIFS(Cleaned_Data!$H$2:$H$158,Cleaned_Data!$E$2:$E$158,K3) -> 186.36585 | N3: Passenger | O3: =SUMIFS(Cleaned_Data!$C$2:$C$158,Cleaned_Data!$E$2:$E$158,N3) -> 5015.184 | Q3: Total Sales ($000s) | R3: =SUM(Cleaned_Data!$C$2:$C$158) -> 8320.698
A4: Dodge | B4: =SUMIFS(Cleaned_Data!$C$2:$C$158,Cleaned_Data!$A$2:$A$158,A4) -> 910.149 | D4: Passenger | E4: =AVERAGEIFS(Cleaned_Data!$F$2:$F$158,Cleaned_Data!$E$2:$E$158,D4) -> 27.719509 | G4: Ford | H4: Explorer | I4: =SUMIFS(Cleaned_Data!$C$2:$C$158,Cleaned_Data!$A$2:$A$158,G4,Cleaned_Data!$B$2:$B$158,H4) -> 276.747 | K4: Passenger | L4: =AVERAGEIFS(Cleaned_Data!$H$2:$H$158,Cleaned_Data!$E$2:$E$158,K4) -> 185.7931 | N4: Car | O4: =SUMIFS(Cleaned_Data!$C$2:$C$158,Cleaned_Data!$E$2:$E$158,N4) -> 3305.514 | Q4: Average Price ($000s) | R4: =AVERAGE(Cleaned_Data!$F$2:$F$158) -> 27.339707
A5: Toyota | B5: =SUMIFS(Cleaned_Data!$C$2:$C$158,Cleaned_Data!$A$2:$A$158,A5) -> 740.205 | G5: Toyota | H5: Camry | I5: =SUMIFS(Cleaned_Data!$C$2:$C$158,Cleaned_Data!$A$2:$A$158,G5,Cleaned_Data!$B$2:$B$158,H5) -> 247.994 | Q5: Average Horsepower | R5: =AVERAGE(Cleaned_Data!$H$2:$H$158) -> 185.94268
A6: Honda | B6: =SUMIFS(Cleaned_Data!$C$2:$C$158,Cleaned_Data!$A$2:$A$158,A6) -> 592.674 | G6: Ford | H6: Taurus | I6: =SUMIFS(Cleaned_Data!$C$2:$C$158,Cleaned_Data!$A$2:$A$158,G6,Cleaned_Data!$B$2:$B$158,H6) -> 245.815 | Q6: Total Number of Models | R6: =COUNTA(Cleaned_Data!$B$2:$B$158) -> 157
A7: Chevrolet | B7: =SUMIFS(Cleaned_Data!$C$2:$C$158,Cleaned_Data!$A$2:$A$158,A7) -> 554.365 | G7: Honda | H7: Accord | I7: =SUMIFS(Cleaned_Data!$C$2:$C$158,Cleaned_Data!$A$2:$A$158,G7,Cleaned_Data!$B$2:$B$158,H7) -> 230.902 | Q7: Total Number of Manufacturers | R7: =COUNTA(A3:A32) -> 30
A8: Nissan | B8: =SUMIFS(Cleaned_Data!$C$2:$C$158,Cleaned_Data!$A$2:$A$158,A8) -> 399.635 | G8: Dodge | H8: Ram Pickup | I8: =SUMIFS(Cleaned_Data!$C$2:$C$158,Cleaned_Data!$A$2:$A$158,G8,Cleaned_Data!$B$2:$B$158,H8) -> 227.061
A9: Pontiac | B9: =SUMIFS(Cleaned_Data!$C$2:$C$158,Cleaned_Data!$A$2:$A$158,A9) -> 370.534 | G9: Ford | H9: Ranger | I9: =SUMIFS(Cleaned_Data!$C$2:$C$158,Cleaned_Data!$A$2:$A$158,G9,Cleaned_Data!$B$2:$B$158,H9) -> 220.65
A10: Jeep | B10: =SUMIFS(Cleaned_Data!$C$2:$C$158,Cleaned_Data!$A$2:$A$158,A10) -> 293.153 | G10: Honda | H10: Civic | I10: =SUMIFS(Cleaned_Data!$C$2:$C$158,Cleaned_Data!$A$2:$A$158,G10,Cleaned_Data!$B$2:$B$158,H10) -> 199.685
A11: Buick | B11: =SUMIFS(Cleaned_Data!$C$2:$C$158,Cleaned_Data!$A$2:$A$158,A11) -> 242.019 | G11: Dodge | H11: Caravan | I11: =SUMIFS(Cleaned_Data!$C$2:$C$158,Cleaned_Data!$A$2:$A$158,G11,Cleaned_Data!$B$2:$B$158,H11) -> 181.749
A12: Mercury | B12: =SUMIFS(Cleaned_Data!$C$2:$C$158,Cleaned_Data!$A$2:$A$158,A12) -> 237.999 | G12: Ford | H12: Focus | I12: =SUMIFS(Cleaned_Data!$C$2:$C$158,Cleaned_Data!$A$2:$A$158,G12,Cleaned_Data!$B$2:$B$158,H12) -> 175.67
A13: Volkswagen | B13: =SUMIFS(Cleaned_Data!$C$2:$C$158,Cleaned_Data!$A$2:$A$158,A13) -> 209.212
A14: Chrysler | B14: =SUMIFS(Cleaned_Data!$C$2:$C$158,Cleaned_Data!$A$2:$A$158,A14) -> 201.721
A15: Mitsubishi | B15: =SUMIFS(Cleaned_Data!$C$2:$C$158,Cleaned_Data!$A$2:$A$158,A15) -> 180.895
A16: Oldsmobile | B16: =SUMIFS(Cleaned_Data!$C$2:$C$158,Cleaned_Data!$A$2:$A$158,A16) -> 178.989
A17: Saturn | B17: =SUMIFS(Cleaned_Data!$C$2:$C$158,Cleaned_Data!$A$2:$A$158,A17) -> 168.85
A18: Hyundai | B18: =SUMIFS(Cleaned_Data!$C$2:$C$158,Cleaned_Data!$A$2:$A$158,A18) -> 137.326
A19: Mercedes-B | B19: =SUMIFS(Cleaned_Data!$C$2:$C$158,Cleaned_Data!$A$2:$A$158,A19) -> 117.125
A20: Cadillac | B20: =SUMIFS(Cleaned_Data!$C$2:$C$158,Cleaned_Data!$A$2:$A$158,A20) -> 112.178
A21: Lexus | B21: =SUMIFS(Cleaned_Data!$C$2:$C$158,Cleaned_Data!$A$2:$A$158,A21) -> 106.843
A22: Lincoln | B22: =SUMIFS(Cleaned_Data!$C$2:$C$158,Cleaned_Data!$A$2:$A$158,A22) -> 85.634
A23: Subaru | B23: =SUMIFS(Cleaned_Data!$C$2:$C$158,Cleaned_Data!$A$2:$A$158,A23) -> 80.135
A24: Acura | B24: =SUMIFS(Cleaned_Data!$C$2:$C$158,Cleaned_Data!$A$2:$A$158,A24) -> 79.005
... A32: Porsche | B32: =SUMIFS(Cleaned_Data!$C$2:$C$158,Cleaned_Data!$A$2:$A$158,A32) -> 12.128
